Workbook

Sheet 数据字典
A1: 编码 | B1: 中文名 | C1: 英文名 | D1: 定价系数 | E1: 含亚克力 | F1: 需电源 | G1: RGB
A2: front | B2: 正面发光字 | C2: Front Lit | D2: 1 | E2: 是 | F2: 是 | G2: 否
A3: back | B3: 背面发光字 | C3: Halo Backlit | D3: 1.1 | E3: 是 | F3: 是 | G3: 否
A4: double | B4: 双面发光字 | C4: Dual Lit | D4: 1.2 | E4: 是 | F4: 是 | G4: 否
A5: bottom | B5: 底部发光字 | C5: Bottom Lit | D5: 1.15 | E5: 否 | F5: 是 | G5: 否
A6: korean | B6: 韩式发光字 | C6: Korean Style | D6: 1.15 | E6: 是 | F6: 是 | G6: 否
A7: rgb | B7: RGB绚彩动态字 | C7: RGB Dynamic | D7: 1.3 | E7: 是 | F7: 是 | G7: 是
A8: neon | B8: LED霓虹灯字 | C8: LED Neon | D8: 0.9 | E8: 否 | F8: 是 | G8: 否
A9: mini | B9: 迷你发光字 | C9: Mini LED | D9: 0.8 | E9: 否 | F9: 是 | G9: 否
A10: metal | B10: 金属字(无灯) | C10: Solid Metal | D10: 0.6 | E10: 否 | F10: 否 | G10: 否
A11: acrylic | B11: 亚克力展示品 | C11: Acrylic Display | D11: 0.7 | E11: 否 | F11: 否 | G11: 否
A12: flat | B12: 平雕字(无灯) | C12: Flat Letter | D12: 0.55 | E12: 否 | F12: 否 | G12: 否
A15: 材质单价表
A16: 编码 | B16: 中文名 | C16: 英文名 | D16: 类型 | E16: 30-59cm (元/cm) | F16: 60-99cm (元/cm) | G16: ≥100cm (元/㎡) | H16: 可电镀颜色
A17: ss201 | B17: 201不锈钢 | C17: 201 Stainless Steel | D17: 不锈钢 | E17: 5 | F17: 6 | G17: 650 | H17: 钛金/玫瑰金/古铜/枪黑/青古铜
A18: ss304 | B18: 304不锈钢 | C18: 304 Stainless Steel | D18: 不锈钢 | E18: 6 | F18: 7 | G18: 750 | H18: 钛金/玫瑰金/古铜/枪黑/青古铜
A19: ss316 | B19: 316不锈钢 | C19: 316 Stainless Steel | D19: 不锈钢 | E19: 7 | F19: 8 | G19: 850 | H19: 无
A20: zn | B20: 镀锌板 | C20: Galvanized Steel | D20: 铁类 | E20: 4.5 | F20: 5.5 | G20: 600 | H20: 无
A21: zn_paint | B21: 镀锌板烤漆 | C21: Painted Galvanized | D21: 铁类 | E21: 5 | F21: 6 | G21: 650 | H21: 无
A22: ti_gold | B22: 钛金板 | C22: Titanium Gold | D22: 电镀类 | E22: 9 | F22: 10 | G22: 1000 | H22: 无(电镀色)
A23: rose_gold | B23: 玫瑰金板 | C23: Rose Gold | D23: 电镀类 | E23: 9 | F23: 10 | G23: 1000 | H23: 无(电镀色)
A24: antique_bz | B24: 古铜板 | C24: Antique Bronze | D24: 电镀类 | E24: 8.5 | F24: 9.5 | G24: 950 | H24: 无(电镀色)
A25: gun_black | B25: 枪黑板 | C25: Gun Black | D25: 电镀类 | E25: 8.5 | F25: 9.5 | G25: 950 | H25: 无(电镀色)
A26: green_bz | B26: 青古铜板 | C26: Green Bronze | D26: 电镀类 | E26: 9 | F26: 10 | G26: 1000 | H26: 无(电镀色)
A29: LED色温表
A30: 序号 | B30: 色温 | C30: 色温(K) | D30: 适合场景
A31: 1 | B31: 暖白 | C31: 3000K | D31: 室内/餐厅/温馨氛围
A32: 2 | B32: 自然白 | C32: 4000K | D32: 通用/办公室/商业空间
A33: 3 | B33: 冷白 | C33: 6000K | D33: 户外/工厂/明亮效果
A34: 4 | B34: 正白光 | C34: 8000K | D34: 高亮招牌/户外广告
A35: 5 | B35: RGB | C35: 全彩 | D35: 炫彩动态/节日装饰
A38: 汇率参数
A39: 内部汇率 | B39: 6.8 | C39: 1 USD = 6.8 CNY
A40: 客户汇率(默认) | B40: 6.6 | C40: 1 USD = 6.6 CNY

Sheet 报价计算器
A1: 博汇 GLOWFORGE 发光字报价计算器
A3: === 输入参数 ===
A5: 产品类型 | B5: 正面发光字 | C5: 从下拉菜单选择
A6: 材质 | B6: 304不锈钢 | C6: 从下拉菜单选择
A7: 宽度(cm) | B7: 50 | C7: 输入数字
A8: 高度(cm) | B8: 50 | C8: 输入数字
A9: 厚度(cm) | B9: 8 | C9: 输入数字
A10: 数量 | B10: 1 | C10: 输入数字
A11: 加价率(%) | B11: 30 | C11: 默认30
A12: USD汇率 | B12: 6.6 | C12: 默认6.6
A14: === 中间计算 ===
A15: 最大边长 maxLen (cm) | B15: =MAX(B7,B8)
A16: 面积 (㎡) | B16: =B7*B8/10000
A17: 定价系数 | B17: =IFERROR(VLOOKUP(B5,'数据字典'!$B$1:$G$12,3,0),1)
A18: cm档单价 (元/cm) | B18: =IF(B15<60,VLOOKUP(B6,'数据字典'!$B$16:$H$26,4,0),IF(B15<100,VLOOKUP(B6,'数据字典'!$B$16:$H$26,5,0),0))
A19: ㎡档单价 (元/㎡) | B19: =VLOOKUP(B6,'数据字典'!$B$16:$H$26,6,0)
A20: 是否电镀材质 | B20: =IF(OR(B6="ti_gold",B6="rose_gold",B6="antique_bz",B6="gun_black",B6="green_bz"),"是","否")
A21: 是否需电源 | B21: =IFERROR(VLOOKUP(B5,'数据字典'!$B$1:$G$12,5,0),"否")
A22: 是否RGB | B22: =IFERROR(VLOOKUP(B5,'数据字典'!$B$1:$G$12,6,0),"否")
A24: === 报价计算结果 ===
A25: 基础价 (元) | B25: =IF(B15<100,B15*B18*B10,B16*B19*B10) | C25: maxLen<100? maxLen×cm单价×数量 : 面积×㎡单价×数量
A26: 净价 (元) | B26: =B25*B17 | C26: =基础价 × 定价系数
A27: 大面积附加费 (元) | B27: =IF(AND(B15>=100,B20="否"),B16*100*B10,0) | C27: 非电镀且maxLen≥100: 面积×100×数量
A28: 电镀费 (元) | B28: =IF(B20="是",IF(B15<100,B15*2.5*B10,B16*250*B10),0) | C28: 电镀材质: maxLen<100? maxLen×2.5×数量 : 面积×250×数量
A29: 木箱费 (元) | B29: =B16*B9/100*350*B10 | C29: 面积×厚度/100×350×数量 (估算)
A30: 电源费 (元) | B30: =IF(B21="是",IF(AND(B22="是",(B7+B8)*B10/100<3),360,CEILING((B7+B8)/100*2*B10*12*1.15/400,1)*150),0) | C30: 需电源? RGB小单360套餐/大单按功率: ceil(周长×12W/m×1.15/400)×150
A31: 配件费 (元) | B31: =B10*3+10 | C31: 螺丝(数量×3)+安装模板(10元)
A32: 服务费 (元) | B32: =(B26+B27+B28+B29)*0.1 | C32: (净价+大面积+电镀+木箱)×10%
A33: 内部成本总计 (元) | B33: =SUM(B25:B32) | C33: 以上各项之和
A34: ★ 正式报价 (RMB) | B34: =B33*(1+B11/100) | C34: =内部成本 × (1+加价率)
A35: ★ 正式报价 (USD) | B35: =B34/B12 | C35: =RMB报价 ÷ USD汇率
A37: 使用说明:
A38: 1. 黄色格子 = 输入参数，可直接修改或从下拉菜单选择
A39: 2. 绿色格子 = 中间计算，自动生成无需修改
A40: 3. 红色/金色格子 = 最终报价结果
A41: 4. 修改任意黄色格子，所有结果自动更新
A42: 5. 不同产品类型/材质切换，公式自动适配
A44: 完整公式参考:
A45: 净价 = maxLen<100 ? maxLen×cm单价×数量×系数 : 面积×㎡单价×数量×系数
A46: 大面积附加费 = 非电镀材质且maxLen≥100cm ? 面积×100×数量 : 0
...
